<?xml version="1.0" encoding="UTF-8"?>
<testng-results skipped="0" failed="1" ignored="0" total="1" passed="0">
  <reporter-output>
    <line>
      <![CDATA[User Created]]>
    </line>
    <line>
      <![CDATA[createUser  2]]>
    </line>
  </reporter-output>
  <suite name="Suite" duration-ms="25" started-at="2020-03-03T14:00:53Z" finished-at="2020-03-03T14:00:53Z">
    <groups>
    </groups>
    <test name="Default test" duration-ms="25" started-at="2020-03-03T14:00:53Z" finished-at="2020-03-03T14:00:53Z">
      <class name="test.second.DemoA">
        <test-method status="FAIL" signature="createUser()[pri:0, instance:test.second.DemoA@71318ec4]" name="createUser" duration-ms="7" started-at="2020-03-03T14:00:53Z" finished-at="2020-03-03T14:00:53Z">
          <exception class="java.lang.AssertionError">
            <message>
              <![CDATA[null]]>
            </message>
            <full-stacktrace>
              <![CDATA[java.lang.AssertionError: null
at org.testng.Assert.fail(Assert.java:96)
at org.testng.Assert.fail(Assert.java:103)
at test.second.DemoA.createUser(DemoA.java:16)
at sun.reflect.NativeMethodAccessorImpl.invoke0(Native Method)
at sun.reflect.NativeMethodAccessorImpl.invoke(Unknown Source)
at sun.reflect.DelegatingMethodAccessorImpl.invoke(Unknown Source)
at java.lang.reflect.Method.invoke(Unknown Source)
at org.testng.internal.MethodInvocationHelper.invokeMethod(MethodInvocationHelper.java:124)
at org.testng.internal.Invoker.invokeMethod(Invoker.java:583)
at org.testng.internal.Invoker.invokeTestMethod(Invoker.java:719)
at org.testng.internal.Invoker.invokeTestMethods(Invoker.java:989)
at org.testng.internal.TestMethodWorker.invokeTestMethods(TestMethodWorker.java:125)
at org.testng.internal.TestMethodWorker.run(TestMethodWorker.java:109)
at org.testng.TestRunner.privateRun(TestRunner.java:648)
at org.testng.TestRunner.run(TestRunner.java:505)
at org.testng.SuiteRunner.runTest(SuiteRunner.java:455)
at org.testng.SuiteRunner.runSequentially(SuiteRunner.java:450)
at org.testng.SuiteRunner.privateRun(SuiteRunner.java:415)
at org.testng.SuiteRunner.run(SuiteRunner.java:364)
at org.testng.SuiteRunnerWorker.runSuite(SuiteRunnerWorker.java:52)
at org.testng.SuiteRunnerWorker.run(SuiteRunnerWorker.java:84)
at org.testng.TestNG.runSuitesSequentially(TestNG.java:1208)
at org.testng.TestNG.runSuitesLocally(TestNG.java:1137)
at org.testng.TestNG.runSuites(TestNG.java:1049)
at org.testng.TestNG.run(TestNG.java:1017)
at org.testng.remote.AbstractRemoteTestNG.run(AbstractRemoteTestNG.java:114)
at org.testng.remote.RemoteTestNG.initAndRun(RemoteTestNG.java:251)
at org.testng.remote.RemoteTestNG.main(RemoteTestNG.java:77)
]]>
            </full-stacktrace>
          </exception> <!-- java.lang.AssertionError -->
          <reporter-output>
            <line>
              <![CDATA[User Created]]>
            </line>
          </reporter-output>
        </test-method> <!-- createUser -->
        <test-method status="PASS" signature="testA(org.testng.ITestResult)[pri:0, instance:test.second.DemoA@71318ec4]" name="testA" is-config="true" duration-ms="1" started-at="2020-03-03T14:00:53Z" finished-at="2020-03-03T14:00:53Z">
          <params>
            <param index="0">
              <value>
                <![CDATA[[TestResult name=createUser status=FAILURE method=DemoA.createUser()[pri:0, instance:test.second.DemoA@71318ec4] output=User Created]]]>
              </value>
            </param>
          </params>
          <reporter-output>
            <line>
              <![CDATA[createUser  2]]>
            </line>
          </reporter-output>
        </test-method> <!-- testA -->
      </class> <!-- test.second.DemoA -->
    </test> <!-- Default test -->
  </suite> <!-- Suite -->
</testng-results>
